description: 'drm/amdgpu: Fix out-of-bounds read of df_v1_7_channel_number'
references:
- https://www.cve.org/CVERecord?id=CVE-2024-46724
- https://git.kernel.org/stable/c/725b728cc0c8c5fafdfb51cb0937870d33a40fa4
- https://git.kernel.org/stable/c/45f7b02afc464c208e8f56bcbc672ef5c364c815
- https://git.kernel.org/stable/c/32915dc909ff502823babfe07d5416c5b6e8a8b1
- https://git.kernel.org/stable/c/f9267972490f9fcffe146e79828e97acc0da588c
- https://git.kernel.org/stable/c/db7a86676fd624768a5d907faf34ad7bb4ff25f4
- https://git.kernel.org/stable/c/d768394fa99467bcf2703bde74ddc96eeb0b71fa
- https://lore.kernel.org/linux-cve-announce/2024091835-CVE-2024-46724-02f5@gregkh/
- https://git.kernel.org/linus/d768394fa99467bcf2703bde74ddc96eeb0b71fa
- https://ubuntu.com/security/notices/USN-7100-1
- https://ubuntu.com/security/notices/USN-7100-2
- https://ubuntu.com/security/notices/USN-7123-1
comments:
  cip/cip-kernel-sec: There is no mention of the commit that introduced the bug in
    the CVE announcement.Fixed in v6.11-rc1.
  cip/masami: |-
    It looks as if this bug was introduced by commit d99605e (drm/amdgpu/df:
    implement df v1_7 callback functions") in 4.18-rc1.
  debian/carnil: First introducing commit could not be determined.
introduced-by:
  mainline: [d99605ead70efa0dc259c28f9b258184e2b3e77c]
fixed-by:
  cip/5.10: [725b728cc0c8c5fafdfb51cb0937870d33a40fa4]
  cip/5.10-rt: [725b728cc0c8c5fafdfb51cb0937870d33a40fa4]
  cip/6.1: [32915dc909ff502823babfe07d5416c5b6e8a8b1]
  cip/6.1-rt: [32915dc909ff502823babfe07d5416c5b6e8a8b1]
  mainline: [d768394fa99467bcf2703bde74ddc96eeb0b71fa]
  stable/5.10: [725b728cc0c8c5fafdfb51cb0937870d33a40fa4]
  stable/5.15: [45f7b02afc464c208e8f56bcbc672ef5c364c815]
  stable/6.1: [32915dc909ff502823babfe07d5416c5b6e8a8b1]
  stable/6.10: [db7a86676fd624768a5d907faf34ad7bb4ff25f4]
  stable/6.6: [f9267972490f9fcffe146e79828e97acc0da588c]
  ubuntu/focal: [958fa0e01e29ccd4df84431b9243a84774888a2d]
